2022-01-13 17:12:07,389 -  nornir.core -     INFO -        run() - Running task 'Main task call here' with args {} on 1 hosts
2022-01-13 17:12:07,399 - nornir.core.task -    ERROR -      start() - Host 'c9800_1': task 'template_file' failed with traceback:
Traceback (most recent call last):
  File "/home/stian/code/TEST_venv/lib/python3.9/site-packages/nornir/core/task.py", line 99, in start
    r = self.task(self, **self.params)
  File "/home/stian/code/TEST_venv/lib/python3.9/site-packages/nornir_jinja2/plugins/tasks/template_file.py", line 43, in template_file
    text = t.render(host=task.host, **kwargs)
  File "/home/stian/code/TEST_venv/lib/python3.9/site-packages/jinja2/environment.py", line 1291, in render
    self.environment.handle_exception()
  File "/home/stian/code/TEST_venv/lib/python3.9/site-packages/jinja2/environment.py", line 925, in handle_exception
    raise rewrite_traceback_stack(source=source)
  File "templates/04_tacacs_radius.j2", line 6, in top-level template code
    tacacs server {{  ise_server1 }}
jinja2.exceptions.UndefinedError: 'ise_server1' is undefined

2022-01-13 17:12:07,399 - nornir.core.task -    ERROR -      start() - Host 'c9800_1': task 'tacacs_radius' failed with traceback:
Traceback (most recent call last):
  File "/home/stian/code/TEST_venv/lib/python3.9/site-packages/nornir/core/task.py", line 99, in start
    r = self.task(self, **self.params)
  File "/home/stian/code/TEST/c9800_deployment/generate_config.py", line 42, in tacacs_radius
    ren_result = task.run(
  File "/home/stian/code/TEST_venv/lib/python3.9/site-packages/nornir/core/task.py", line 174, in run
    raise NornirSubTaskError(task=run_task, result=r)
nornir.core.exceptions.NornirSubTaskError: Subtask: template_file (failed)


2022-01-13 17:12:07,400 - nornir.core.task -    ERROR -      start() - Host 'c9800_1': task 'Main task call here' failed with traceback:
Traceback (most recent call last):
  File "/home/stian/code/TEST_venv/lib/python3.9/site-packages/nornir/core/task.py", line 99, in start
    r = self.task(self, **self.params)
  File "/home/stian/code/TEST/c9800_deployment/generate_config.py", line 307, in main
    task.run(
  File "/home/stian/code/TEST_venv/lib/python3.9/site-packages/nornir/core/task.py", line 174, in run
    raise NornirSubTaskError(task=run_task, result=r)
nornir.core.exceptions.NornirSubTaskError: Subtask: tacacs_radius (failed)


2022-01-13 17:12:37,942 -  nornir.core -     INFO -        run() - Running task 'Main task call here' with args {} on 1 hosts
2022-01-13 17:12:37,951 - nornir.core.task -    ERROR -      start() - Host 'c9800_1': task 'template_file' failed with traceback:
Traceback (most recent call last):
  File "/home/stian/code/TEST_venv/lib/python3.9/site-packages/nornir/core/task.py", line 99, in start
    r = self.task(self, **self.params)
  File "/home/stian/code/TEST_venv/lib/python3.9/site-packages/nornir_jinja2/plugins/tasks/template_file.py", line 43, in template_file
    text = t.render(host=task.host, **kwargs)
  File "/home/stian/code/TEST_venv/lib/python3.9/site-packages/jinja2/environment.py", line 1291, in render
    self.environment.handle_exception()
  File "/home/stian/code/TEST_venv/lib/python3.9/site-packages/jinja2/environment.py", line 925, in handle_exception
    raise rewrite_traceback_stack(source=source)
  File "templates/04_tacacs_radius.j2", line 6, in top-level template code
    tacacs server {{  ise_server1 }}
jinja2.exceptions.UndefinedError: 'ise_server1' is undefined

2022-01-13 17:12:37,952 - nornir.core.task -    ERROR -      start() - Host 'c9800_1': task 'tacacs_radius' failed with traceback:
Traceback (most recent call last):
  File "/home/stian/code/TEST_venv/lib/python3.9/site-packages/nornir/core/task.py", line 99, in start
    r = self.task(self, **self.params)
  File "/home/stian/code/TEST/c9800_deployment/generate_config.py", line 42, in tacacs_radius
    ren_result = task.run(
  File "/home/stian/code/TEST_venv/lib/python3.9/site-packages/nornir/core/task.py", line 174, in run
    raise NornirSubTaskError(task=run_task, result=r)
nornir.core.exceptions.NornirSubTaskError: Subtask: template_file (failed)


2022-01-13 17:12:37,952 - nornir.core.task -    ERROR -      start() - Host 'c9800_1': task 'Main task call here' failed with traceback:
Traceback (most recent call last):
  File "/home/stian/code/TEST_venv/lib/python3.9/site-packages/nornir/core/task.py", line 99, in start
    r = self.task(self, **self.params)
  File "/home/stian/code/TEST/c9800_deployment/generate_config.py", line 307, in main
    task.run(
  File "/home/stian/code/TEST_venv/lib/python3.9/site-packages/nornir/core/task.py", line 174, in run
    raise NornirSubTaskError(task=run_task, result=r)
nornir.core.exceptions.NornirSubTaskError: Subtask: tacacs_radius (failed)


2022-01-13 17:14:37,149 -  nornir.core -     INFO -        run() - Running task 'Main task call here' with args {} on 1 hosts
2022-01-14 10:50:36,646 -  nornir.core -     INFO -        run() - Running task 'Main task call here' with args {} on 2 hosts
2022-01-14 10:50:36,651 -  nornir.core -     INFO -        run() - Running task 'switch_interfaces' with args {} on 1 hosts
2022-01-14 10:50:36,657 -  nornir.core -     INFO -        run() - Running task 'redundancy' with args {} on 1 hosts
2022-01-14 11:43:35,220 -  nornir.core -     INFO -        run() - Running task 'Main task call here' with args {} on 1 hosts
2022-01-14 11:43:44,308 -  nornir.core -     INFO -        run() - Running task 'Main task call here' with args {} on 2 hosts
2022-01-14 11:43:44,317 -  nornir.core -     INFO -        run() - Running task 'switch_interfaces' with args {} on 1 hosts
2022-01-14 11:43:44,328 -  nornir.core -     INFO -        run() - Running task 'redundancy' with args {} on 1 hosts
